Traceback (most recent call last):
  File "/home/runner/work/forecasting/forecasting/.pixi/envs/doc/lib/python3.12/site-packages/jupyter_core/utils/__init__.py", line 154, in wrapped
    asyncio.get_running_loop()
RuntimeError: no running event loop

During handling of the above exception, another exception occurred:

Traceback (most recent call last):
  File "/home/runner/work/forecasting/forecasting/.pixi/envs/doc/lib/python3.12/site-packages/jupyter_cache/executors/utils.py", line 58, in single_nb_execution
    executenb(
  File "/home/runner/work/forecasting/forecasting/.pixi/envs/doc/lib/python3.12/site-packages/nbclient/client.py", line 1319, in execute
    return NotebookClient(nb=nb, resources=resources, km=km, **kwargs).execute()
           ^^^^^^^^^^^^^^^^^^^^^^^^^^^^^^^^^^^^^^^^^^^^^^^^^^^^^^^^^^^^^^^^^^^^^
  File "/home/runner/work/forecasting/forecasting/.pixi/envs/doc/lib/python3.12/site-packages/jupyter_core/utils/__init__.py", line 158, in wrapped
    return loop.run_until_complete(inner)
           ^^^^^^^^^^^^^^^^^^^^^^^^^^^^^^
  File "/home/runner/work/forecasting/forecasting/.pixi/envs/doc/lib/python3.12/asyncio/base_events.py", line 691, in run_until_complete
    return future.result()
           ^^^^^^^^^^^^^^^
  File "/home/runner/work/forecasting/forecasting/.pixi/envs/doc/lib/python3.12/site-packages/nbclient/client.py", line 709, in async_execute
    await self.async_execute_cell(
  File "/home/runner/work/forecasting/forecasting/.pixi/envs/doc/lib/python3.12/site-packages/nbclient/client.py", line 1062, in async_execute_cell
    await self._check_raise_for_error(cell, cell_index, exec_reply)
  File "/home/runner/work/forecasting/forecasting/.pixi/envs/doc/lib/python3.12/site-packages/nbclient/client.py", line 918, in _check_raise_for_error
    raise CellExecutionError.from_cell_and_msg(cell, exec_reply_content)
nbclient.exceptions.CellExecutionError: An error occurred while executing the following cell:
------------------
import datetime
import tzdata  # noqa: F401
import pandas as pd
from pyarrow.parquet import read_table

import altair
import numpy as np
import polars as pl
import skrub
from pathlib import Path
import holidays
import warnings

from tutorial_helpers import (
    binned_coverage,
    plot_lorenz_curve,
    plot_reliability_diagram,
    plot_residuals_vs_predicted,
    plot_binned_residuals,
    plot_horizon_forecast,
)

# Ignore warnings from pkg_resources triggered by Python 3.13's multiprocessing.
warnings.filterwarnings("ignore", category=UserWarning, module="pkg_resources")
------------------


[31m---------------------------------------------------------------------------[39m
[31mModuleNotFoundError[39m                       Traceback (most recent call last)
[36mCell[39m[36m [39m[32mIn[2][39m[32m, line 14[39m
[32m     11[39m [38;5;28;01mimport[39;00m[38;5;250m [39m[34;01mholidays[39;00m
[32m     12[39m [38;5;28;01mimport[39;00m[38;5;250m [39m[34;01mwarnings[39;00m
[32m---> [39m[32m14[39m [38;5;28;01mfrom[39;00m[38;5;250m [39m[34;01mtutorial_helpers[39;00m[38;5;250m [39m[38;5;28;01mimport[39;00m (
[32m     15[39m     binned_coverage,
[32m     16[39m     plot_lorenz_curve,
[32m     17[39m     plot_reliability_diagram,
[32m     18[39m     plot_residuals_vs_predicted,
[32m     19[39m     plot_binned_residuals,
[32m     20[39m     plot_horizon_forecast,
[32m     21[39m )
[32m     23[39m [38;5;66;03m# Ignore warnings from pkg_resources triggered by Python 3.13's multiprocessing.[39;00m
[32m     24[39m warnings.filterwarnings([33m"[39m[33mignore[39m[33m"[39m, category=[38;5;167;01mUserWarning[39;00m, module=[33m"[39m[33mpkg_resources[39m[33m"[39m)

[31mModuleNotFoundError[39m: No module named 'tutorial_helpers'

